<?xml version="1.0"?>

<robot xmlns:xacro="http://www.ros.org/wiki/xacro">

  <xacro:macro name="diffbot" params="prefix">

  <material name="grey">
    <color rgba="0.5 0.5 0.5 1.0"/>
  </material>

  <material name="white">
    <color rgba="1 1 1 1.0"/>
  </material>

  <material name="green">
    <color rgba="0 0.7 0.0 1.0"/>
  </material>

  <link name="base_footprint">
    
  </link>

  <link name="base_link">
    <visual>
        <geometry>
          <box size="0.6 0.4 0.2"/>
        </geometry>
        <origin xyz="0.0 0.0 0.1" rpy="0.0 0.0 0.0"/>
        <material name="green"/>
    </visual>
  </link>

  <link name="lidar_link">
    <visual>
      <origin xyz="0.0 0.0 0" rpy="0.0 0.0 0.0"/>
      <geometry>
        <cylinder radius="0.1" length="0.05"/>
      </geometry>
      <material name="white"/>
    </visual>
  </link>
  
  <link name="right_wheel_link">
    <visual>
      <origin xyz="0.0 0.0 0.0" rpy="0.0 0.0 0.0"/>
      <geometry>
        <cylinder radius="0.1" length="0.05"/>
      </geometry>
      <material name="grey"/>
    </visual>
  </link>

  <link name="left_wheel_link">
    <visual>
      <origin xyz="0.0 0.0 0.0" rpy="0.0 0.0 0.0"/>
      <geometry>
        <cylinder radius="0.1" length="0.05"/>
      </geometry>
      <material name="grey"/>
    </visual>
  </link>

  <link name="castor_link">
    <visual name="">
      <origin xyz="0.0 0.0 0.0" rpy="0.0 0.0 0.0"/>
      <geometry>
        <sphere radius="0.05"/>      
      </geometry>
      <material name="grey"/>
    </visual>
  </link>

  <joint name="base_joint" type="fixed">
    <origin xyz="0.0 0.0 0.1" rpy="0.0 0.0 0.0"/>
    <parent link="base_footprint"/>
    <child link="base_link"/>
  </joint>

  <joint name="base_lidar_joint" type="fixed">
    <origin xyz="0.0 0.0 0.225" rpy="0.0 0.0 0.0"/>
    <parent link="base_link"/>
    <child link="lidar_link"/>
    <axis xyz="0.0 0.0 0.0"/>
  </joint>

  <joint name="right_wheel_joint" type="continuous">
    <origin xyz="0.2 0.225 0.0" rpy="1.5708 0.0 0.0"/>
    <parent link="base_link"/>
    <child link="right_wheel_link"/>
    <axis xyz="0 0 1"/>
  </joint>

  <joint name="left_wheel_joint" type="continuous">
    <origin xyz="0.2 -0.225 0.0" rpy="1.5708 0.0 0.0"/>
    <parent link="base_link"/>
    <child link="left_wheel_link"/>
    <axis xyz="0 0 1"/>
  </joint>

  <joint name="castor_joint" type="fixed">
    <origin xyz="-0.15 0.0 -0.025" rpy="0.0 0.0 0.0"/>
    <parent link="base_link"/>
    <child link="castor_link"/>
    <axis xyz="0.0 0.0 0.0"/>
  </joint>

  </xacro:macro>

</robot>
